<?xml version="1.0"?>
<robot xmlns:xacro="http://www.ros.org/wiki/xacro">

  <xacro:include filename="$(find kuka_iiwa_description)/robots/materials.xacro"/>

  <xacro:macro name="iiwa14" params="prefix:='iiwa14_' connected_to:='' xyz:='0 0 0' rpy:='0 0 0'">
    <xacro:if value="${connected_to == ''}">
      <link name="world"/>
      <xacro:property name="base_frame_name" value="world"/>
    </xacro:if>
    <xacro:unless value="${connected_to == ''}">
      <xacro:property name="base_frame_name" value="${connected_to}"/>
    </xacro:unless>

    <joint name="${prefix}to_${base_frame_name}" type="fixed">
      <parent link="${base_frame_name}"/>
      <child link="${prefix}link0"/>
      <origin rpy="${rpy}" xyz="${xyz}"/>
    </joint>

    <link name="${prefix}link0">
      <inertial>
        <origin xyz="-0.1 0 0.07" rpy="0 0 0"/>
        <mass value="5"/>
        <inertia ixx="0.05"  ixy="0"  ixz="0" iyy="0.06" iyz="0" izz="0.03" />
      </inertial>

      <visual>
        <origin xyz="0 0 0" rpy="0 0 0"/>
        <geometry>
          <mesh filename="package://kuka_iiwa_description/meshes/iiwa14/visual/link_0.stl"/>
        </geometry>
        <material name="Grey"/>
      </visual>

      <collision>
        <origin xyz="0 0 0" rpy="0 0 0"/>
        <geometry>
          <mesh filename="package://kuka_iiwa_description/meshes/iiwa14/collision/link_0.stl"/>
        </geometry>
        <material name="Grey"/>
      </collision>
    </link>

    <joint name="${prefix}joint1" type="revolute">
      <parent link="${prefix}link0"/>
      <child link="${prefix}link1"/>
      <origin xyz="0 0 0.1575" rpy="0 0 0"/>
      <axis xyz="0 0 1"/>
      <limit lower="${-joint_limit_1}" upper="${joint_limit_1}"
             effort="${max_effort_1}" velocity="${max_velocity_1}"/>
    </joint>

    <link name="${prefix}link1">
      <inertial>
        <origin xyz="0 -0.03 0.12" rpy="0 0 0"/>
        <mass value="4"/>
        <inertia ixx="0.1"  ixy="0"  ixz="0" iyy="0.09" iyz="0" izz="0.02" />
      </inertial>

      <visual>
        <origin xyz="0 0 0" rpy="0 0 0"/>
        <geometry>
          <mesh filename="package://kuka_iiwa_description/meshes/iiwa14/visual/link_1.stl"/>
        </geometry>
        <material name="Orange"/>
      </visual>

      <collision>
        <origin xyz="0 0 0" rpy="0 0 0"/>
        <geometry>
          <mesh filename="package://kuka_iiwa_description/meshes/iiwa14/collision/link_1.stl"/>
        </geometry>
        <material name="Orange"/>
      </collision>
    </link>

    <joint name="${prefix}joint2" type="revolute">
      <parent link="${prefix}link1"/>
      <child link="${prefix}link2"/>
      <origin xyz="0 0 0.2025" rpy="${PI / 2}   0 ${PI}"/>
      <axis xyz="0 0 1"/>
      <limit lower="${-joint_limit_2}" upper="${joint_limit_2}"
             effort="${max_effort_2}" velocity="${max_velocity_2}"/>
    </joint>

    <link name="${prefix}link2">
      <inertial>
        <origin xyz="0.0003 0.059 0.042" rpy="0 0 0"/>
        <mass value="4"/>
        <inertia ixx="0.05"  ixy="0"  ixz="0" iyy="0.018" iyz="0" izz="0.044" />
      </inertial>

      <visual>
        <origin xyz="0 0 0" rpy="0 0 0"/>
        <geometry>
          <mesh filename="package://kuka_iiwa_description/meshes/iiwa14/visual/link_2.stl"/>
        </geometry>
        <material name="Orange"/>
      </visual>

      <collision>
        <origin xyz="0 0 0" rpy="0 0 0"/>
        <geometry>
          <mesh filename="package://kuka_iiwa_description/meshes/iiwa14/collision/link_2.stl"/>
        </geometry>
        <material name="Orange"/>
      </collision>
    </link>

    <joint name="${prefix}joint3" type="revolute">
      <parent link="${prefix}link2"/>
      <child link="${prefix}link3"/>
      <origin xyz="0 0.2045 0" rpy="${PI / 2} 0 ${PI}"/>
      <axis xyz="0 0 1"/>
      <limit lower="${-joint_limit_3}" upper="${joint_limit_3}"
             effort="${max_effort_3}" velocity="${max_velocity_3}"/>
    </joint>

    <link name="${prefix}link3">
      <inertial>
        <origin xyz="0 0.03 0.13" rpy="0 0 0"/>
        <mass value="3"/>
        <inertia ixx="0.08"  ixy="0"  ixz="0" iyy="0.075" iyz="0" izz="0.01" />
      </inertial>

      <visual>
        <origin xyz="0 0 0" rpy="0 0 0"/>
        <geometry>
          <mesh filename="package://kuka_iiwa_description/meshes/iiwa14/visual/link_3.stl"/>
        </geometry>
        <material name="Orange"/>
      </visual>

      <collision>
        <origin xyz="0 0 0" rpy="0 0 0"/>
        <geometry>
          <mesh filename="package://kuka_iiwa_description/meshes/iiwa14/collision/link_3.stl"/>
        </geometry>
        <material name="Orange"/>
      </collision>
    </link>

    <joint name="${prefix}joint4" type="revolute">
      <parent link="${prefix}link3"/>
      <child link="${prefix}link4"/>
      <origin xyz="0 0 0.2155" rpy="${PI / 2} 0 0"/>
      <axis xyz="0 0 1"/>
      <limit lower="${-joint_limit_4}" upper="${joint_limit_4}"
             effort="${max_effort_4}" velocity="${max_velocity_4}"/>
    </joint>

    <link name="${prefix}link4">
      <inertial>
        <origin xyz="0 0.067 0.034" rpy="0 0 0"/>
        <mass value="2.7"/>
        <inertia ixx="0.03"  ixy="0"  ixz="0" iyy="0.01" iyz="0" izz="0.029" />
      </inertial>

      <visual>
        <origin xyz="0 0 0" rpy="0 0 0"/>
        <geometry>
          <mesh filename="package://kuka_iiwa_description/meshes/iiwa14/visual/link_4.stl"/>
        </geometry>
        <material name="Orange"/>
      </visual>

      <collision>
        <origin xyz="0 0 0" rpy="0 0 0"/>
        <geometry>
          <mesh filename="package://kuka_iiwa_description/meshes/iiwa14/collision/link_4.stl"/>
        </geometry>
        <material name="Orange"/>
      </collision>
    </link>

    <joint name="${prefix}joint5" type="revolute">
      <parent link="${prefix}link4"/>
      <child link="${prefix}link5"/>
      <origin xyz="0 0.1845 0" rpy="${-PI / 2} ${PI} 0"/>
      <axis xyz="0 0 1"/>
      <limit lower="${-joint_limit_5}" upper="${joint_limit_5}"
             effort="${max_effort_5}" velocity="${max_velocity_5}"/>
    </joint>

    <link name="${prefix}link5">
      <inertial>
        <origin xyz="0.0001 0.021 0.076" rpy="0 0 0"/>
        <mass value="1.7"/>
        <inertia ixx="0.02"  ixy="0"  ixz="0" iyy="0.018" iyz="0" izz="0.005" />
      </inertial>

      <visual>
        <origin xyz="0 0 0" rpy="0 0 0"/>
        <geometry>
          <mesh filename="package://kuka_iiwa_description/meshes/iiwa14/visual/link_5.stl"/>
        </geometry>
        <material name="Orange"/>
      </visual>

      <collision>
        <origin xyz="0 0 0" rpy="0 0 0"/>
        <geometry>
          <mesh filename="package://kuka_iiwa_description/meshes/iiwa14/collision/link_5.stl"/>
        </geometry>
        <material name="Orange"/>
      </collision>
    </link>

    <joint name="${prefix}joint6" type="revolute">
      <parent link="${prefix}link5"/>
      <child link="${prefix}link6"/>
      <origin xyz="0 0 0.2155" rpy="${PI / 2} 0 0"/>
      <axis xyz="0 0 1"/>
      <limit lower="${-joint_limit_6}" upper="${joint_limit_6}"
             effort="${max_effort_6}" velocity="${max_velocity_6}"/>
    </joint>

    <link name="${prefix}link6">
      <inertial>
        <origin xyz="0 0.0006 0.0004" rpy="0 0 0"/>
        <mass value="1.8"/>
        <inertia ixx="0.005"  ixy="0"  ixz="0" iyy="0.0036" iyz="0" izz="0.0047" />
      </inertial>

      <visual>
        <origin xyz="0 0 0" rpy="0 0 0"/>
        <geometry>
          <mesh filename="package://kuka_iiwa_description/meshes/iiwa14/visual/link_6.stl"/>
        </geometry>
        <material name="Orange"/>
      </visual>

      <collision>
        <origin xyz="0 0 0" rpy="0 0 0"/>
        <geometry>
          <mesh filename="package://kuka_iiwa_description/meshes/iiwa14/collision/link_6.stl"/>
        </geometry>
        <material name="Orange"/>
      </collision>
    </link>

    <joint name="${prefix}joint7" type="revolute">
      <parent link="${prefix}link6"/>
      <child link="${prefix}link7"/>
      <origin xyz="0 0.081 0" rpy="${- PI / 2} ${PI} 0"/>
      <axis xyz="0 0 1"/>
      <limit lower="${-joint_limit_7}" upper="${joint_limit_7}"
             effort="${max_effort_7}" velocity="${max_velocity_7}"/>
    </joint>

    <link name="${prefix}link7">
      <inertial>
        <origin xyz="0 0 0.02" rpy="0 0 0"/>
        <mass value="0.3"/>
        <inertia ixx="0.001"  ixy="0"  ixz="0" iyy="0.001" iyz="0" izz="0.001" />
      </inertial>

      <visual>
        <origin xyz="0 0 0" rpy="0 0 0"/>
        <geometry>
          <mesh filename="package://kuka_iiwa_description/meshes/iiwa14/visual/link_7.stl"/>
        </geometry>
        <material name="Grey"/>
      </visual>

      <collision>
        <origin xyz="0 0 0" rpy="0 0 0"/>
        <geometry>
          <mesh filename="package://kuka_iiwa_description/meshes/iiwa14/collision/link_7.stl"/>
        </geometry>
        <material name="Grey"/>
      </collision>
    </link>

    <joint name="${prefix}joint8" type="fixed">
      <parent link="${prefix}link7"/>
      <child link="${prefix}link8"/>
      <origin xyz="0 0 0.045" rpy="0 0 0"/>
    </joint>

    <link name="${prefix}link8">
      <inertial>
        <origin xyz="0 0 0" rpy="0 0 0"/>
        <mass value="1e-6"/>
        <inertia ixx="1" ixy="0" ixz="0" iyy="1" iyz="0" izz="1"/>
      </inertial>
    </link>

  </xacro:macro>

</robot>